<?xml version="1.0" ?>
<!-- =================================================================================== -->
<!-- |    This document was autogenerated by xacro from hexumi.xacro                   | -->
<!-- |    EDITING THIS FILE BY HAND IS NOT RECOMMENDED                                 | -->
<!-- =================================================================================== -->
<robot name="hexumi">
  <material name="black_pla">
    <color rgba="0.8 0.8 0.8 1"/>
  </material>
  <material name="red_pla">
    <color rgba="0.9176470588235294 0.22745098039215686 0.1568627450980392 1"/>
  </material>
  <material name="white_pla">
    <color rgba="0.8392156862745098 0.9254901960784314 0.9647058823529412 1"/>
  </material>
  <material name="grey_pla">
    <color rgba="0.4470588235294118 0.5568627450980392 0.6745098039215687 1"/>
  </material>
  <!-- inertia macro -->
  <!-- Build the body frame -->
  <link name="base_link"/>
  <joint name="base_joint" type="fixed">
    <parent link="base_link"/>
    <child link="body"/>
    <origin rpy="0 0 0" xyz="0 0 0"/>
  </joint>
  <link name="body">
    <collision>
      <origin rpy="0 0 0" xyz="0 0 0"/>
      <geometry>
        <mesh filename="file:///home/max/ROS2utorial/URDF/ros2_urdf_ws/install/my_robot_description/share/my_robot_description/meshes/collision/BODY_COLLISIONS.stl" scale="0.001 0.001 0.001"/>
      </geometry>
    </collision>
    <visual>
      <origin rpy="0 0 0" xyz="0 0 0"/>
      <geometry>
        <mesh filename="file:///home/max/ROS2utorial/URDF/ros2_urdf_ws/install/my_robot_description/share/my_robot_description/meshes/visual/BODY.stl" scale="0.001 0.001 0.001"/>
      </geometry>
      <material name="white_pla"/>
    </visual>
    <inertial>
      <origin rpy="0 0 0" xyz="-0.02416 0.00018 0.00977"/>
      <mass value="1.07064"/>
      <inertia ixx="0.00329495565" ixy="-8.18428e-06" ixz="-7.183633e-05" iyy="0.00422550506" iyz="-2.312133e-05" izz="0.00610423987"/>
    </inertial>
  </link>
  <!-- Build robot model -->
  <joint name="virtual_body_joint_R1" type="fixed">
    <origin rpy="0 0 0" xyz="0 0 0"/>
    <parent link="body"/>
    <child link="hip_R1"/>
  </joint>
  <link name="hip_R1">
    <inertial>
      <origin rpy="0 0 0" xyz="0 0 0"/>
      <mass value="0"/>
      <inertia ixx="0" ixy="0" ixz="0" iyy="0" iyz="0" izz="0"/>
    </inertial>
  </link>
  <!-- coxa -->
  <joint name="coxa_joint_R1" type="revolute">
    <origin rpy="0 0 -0.5235987755982988" xyz="0.09526279441628825 -0.05499999999999999 0"/>
    <parent link="hip_R1"/>
    <child link="coxa_R1"/>
    <axis xyz="0 0 1"/>
    <limit effort="100000" lower="-3.141592653589793" upper="3.141592653589793" velocity="10"/>
  </joint>
  <link name="coxa_R1">
    <collision>
      <origin rpy="0 0 0" xyz="0 0 0.002"/>
      <geometry>
        <mesh filename="file:///home/max/ROS2utorial/URDF/ros2_urdf_ws/install/my_robot_description/share/my_robot_description/meshes/collision/COXA_COLLISIONS.stl" scale="0.001 0.001 0.001"/>
      </geometry>
    </collision>
    <visual>
      <origin rpy="0 0 0" xyz="0 0 0.002"/>
      <geometry>
        <mesh filename="file:///home/max/ROS2utorial/URDF/ros2_urdf_ws/install/my_robot_description/share/my_robot_description/meshes/visual/COXA_R.stl" scale="0.001 0.001 0.001"/>
      </geometry>
      <material name="grey_pla"/>
    </visual>
    <inertial>
      <origin rpy="0 0 0" xyz="-0.00708 -0.00983 0.02613"/>
      <mass value="0.011045"/>
      <inertia ixx="4.537796e-05" ixy="8.0667e-07" ixz="-2.6225e-07" iyy="3.512955e-05" iyz="-3.4651e-07" izz="5.818289e-05"/>
    </inertial>
  </link>
  <!-- femur -->
  <joint name="femur_joint_R1" type="revolute">
    <origin rpy="1.5707963267948966 0 0" xyz="0.04 0 0"/>
    <parent link="coxa_R1"/>
    <child link="femur_R1"/>
    <axis xyz="0 0 1"/>
    <limit effort="100000" lower="-3.141592653589793" upper="3.141592653589793" velocity="10"/>
  </joint>
  <link name="femur_R1">
    <visual>
      <origin rpy="0 0 0" xyz="0 0 0"/>
      <geometry>
        <mesh filename="file:///home/max/ROS2utorial/URDF/ros2_urdf_ws/install/my_robot_description/share/my_robot_description/meshes/visual/FEMUR_R.stl" scale="0.001 0.001 0.001"/>
      </geometry>
      <material name="white_pla"/>
    </visual>
    <collision>
      <origin rpy="0 0 0" xyz="0 0 0"/>
      <geometry>
        <mesh filename="file:///home/max/ROS2utorial/URDF/ros2_urdf_ws/install/my_robot_description/share/my_robot_description/meshes/collision/FEMUR_R_COLLISIONS.stl" scale="0.001 0.001 0.001"/>
      </geometry>
    </collision>
    <inertial>
      <origin rpy="0 0 0" xyz="0.035 0.00305 0.03111"/>
      <mass value="0.00514"/>
      <inertia ixx="3.795796e-05" ixy="0" ixz="0" iyy="7.254033e-05" iyz="2.1619e-07" izz="4.000019e-05"/>
    </inertial>
  </link>
  <!-- tibia -->
  <joint name="tibia_joint_R1" type="revolute">
    <origin rpy="0 0 0" xyz="0.07 0 0"/>
    <parent link="femur_R1"/>
    <child link="tibia_R1"/>
    <axis xyz="0 0 1"/>
    <limit effort="100000" lower="-3.141592653589793" upper="3.141592653589793" velocity="10"/>
  </joint>
  <link name="tibia_R1">
    <visual>
      <origin rpy="0 0 -0.2617993877991494" xyz="0 0 0"/>
      <geometry>
        <mesh filename="file:///home/max/ROS2utorial/URDF/ros2_urdf_ws/install/my_robot_description/share/my_robot_description/meshes/visual/TIBIA_R.stl" scale="0.001 0.001 0.001"/>
      </geometry>
      <material name="red_pla"/>
    </visual>
    <collision>
      <origin rpy="0 0 -0.2617993877991494" xyz="0 0 0"/>
      <geometry>
        <mesh filename="file:///home/max/ROS2utorial/URDF/ros2_urdf_ws/install/my_robot_description/share/my_robot_description/meshes/collision/TIBIA_COLLISIONS.stl" scale="0.001 0.001 0.001"/>
      </geometry>
    </collision>
    <inertial>
      <origin rpy="0 0 0" xyz="0.0286 0.0114 0.00028"/>
      <mass value="0.0013722"/>
      <inertia ixx="4.499197e-05" ixy="-5.286863e-05" ixz="1.07479e-06" iyy="0.00019412525" iyz="4.4041e-07" izz="0.00021338222"/>
    </inertial>
  </link>
  <joint name="end_effector_joint_R1" type="fixed">
    <origin rpy="0 0 0" xyz="0.13 0 0"/>
    <parent link="tibia_R1"/>
    <child link="end_effector_R1"/>
  </joint>
  <link name="end_effector_R1">
    <inertial>
      <origin rpy="0 0 0" xyz="0 0 0"/>
      <mass value="0"/>
      <inertia ixx="0" ixy="0" ixz="0" iyy="0" iyz="0" izz="0"/>
    </inertial>
  </link>
  <joint name="virtual_body_joint_R2" type="fixed">
    <origin rpy="0 0 0" xyz="0 0 0"/>
    <parent link="body"/>
    <child link="hip_R2"/>
  </joint>
  <link name="hip_R2">
    <inertial>
      <origin rpy="0 0 0" xyz="0 0 0"/>
      <mass value="0"/>
      <inertia ixx="0" ixy="0" ixz="0" iyy="0" iyz="0" izz="0"/>
    </inertial>
  </link>
  <!-- coxa -->
  <joint name="coxa_joint_R2" type="revolute">
    <origin rpy="0 0 -1.5707963267948966" xyz="5.5109105961630896e-18 -0.09 0"/>
    <parent link="hip_R2"/>
    <child link="coxa_R2"/>
    <axis xyz="0 0 1"/>
    <limit effort="100000" lower="-3.141592653589793" upper="3.141592653589793" velocity="10"/>
  </joint>
  <link name="coxa_R2">
    <collision>
      <origin rpy="0 0 0" xyz="0 0 0.002"/>
      <geometry>
        <mesh filename="file:///home/max/ROS2utorial/URDF/ros2_urdf_ws/install/my_robot_description/share/my_robot_description/meshes/collision/COXA_COLLISIONS.stl" scale="0.001 0.001 0.001"/>
      </geometry>
    </collision>
    <visual>
      <origin rpy="0 0 0" xyz="0 0 0.002"/>
      <geometry>
        <mesh filename="file:///home/max/ROS2utorial/URDF/ros2_urdf_ws/install/my_robot_description/share/my_robot_description/meshes/visual/COXA_R.stl" scale="0.001 0.001 0.001"/>
      </geometry>
      <material name="grey_pla"/>
    </visual>
    <inertial>
      <origin rpy="0 0 0" xyz="-0.00708 -0.00983 0.02613"/>
      <mass value="0.011045"/>
      <inertia ixx="4.537796e-05" ixy="8.0667e-07" ixz="-2.6225e-07" iyy="3.512955e-05" iyz="-3.4651e-07" izz="5.818289e-05"/>
    </inertial>
  </link>
  <!-- femur -->
  <joint name="femur_joint_R2" type="revolute">
    <origin rpy="1.5707963267948966 0 0" xyz="0.04 0 0"/>
    <parent link="coxa_R2"/>
    <child link="femur_R2"/>
    <axis xyz="0 0 1"/>
    <limit effort="100000" lower="-3.141592653589793" upper="3.141592653589793" velocity="10"/>
  </joint>
  <link name="femur_R2">
    <visual>
      <origin rpy="0 0 0" xyz="0 0 0"/>
      <geometry>
        <mesh filename="file:///home/max/ROS2utorial/URDF/ros2_urdf_ws/install/my_robot_description/share/my_robot_description/meshes/visual/FEMUR_R.stl" scale="0.001 0.001 0.001"/>
      </geometry>
      <material name="white_pla"/>
    </visual>
    <collision>
      <origin rpy="0 0 0" xyz="0 0 0"/>
      <geometry>
        <mesh filename="file:///home/max/ROS2utorial/URDF/ros2_urdf_ws/install/my_robot_description/share/my_robot_description/meshes/collision/FEMUR_R_COLLISIONS.stl" scale="0.001 0.001 0.001"/>
      </geometry>
    </collision>
    <inertial>
      <origin rpy="0 0 0" xyz="0.035 0.00305 0.03111"/>
      <mass value="0.00514"/>
      <inertia ixx="3.795796e-05" ixy="0" ixz="0" iyy="7.254033e-05" iyz="2.1619e-07" izz="4.000019e-05"/>
    </inertial>
  </link>
  <!-- tibia -->
  <joint name="tibia_joint_R2" type="revolute">
    <origin rpy="0 0 0" xyz="0.07 0 0"/>
    <parent link="femur_R2"/>
    <child link="tibia_R2"/>
    <axis xyz="0 0 1"/>
    <limit effort="100000" lower="-3.141592653589793" upper="3.141592653589793" velocity="10"/>
  </joint>
  <link name="tibia_R2">
    <visual>
      <origin rpy="0 0 -0.2617993877991494" xyz="0 0 0"/>
      <geometry>
        <mesh filename="file:///home/max/ROS2utorial/URDF/ros2_urdf_ws/install/my_robot_description/share/my_robot_description/meshes/visual/TIBIA_R.stl" scale="0.001 0.001 0.001"/>
      </geometry>
      <material name="red_pla"/>
    </visual>
    <collision>
      <origin rpy="0 0 -0.2617993877991494" xyz="0 0 0"/>
      <geometry>
        <mesh filename="file:///home/max/ROS2utorial/URDF/ros2_urdf_ws/install/my_robot_description/share/my_robot_description/meshes/collision/TIBIA_COLLISIONS.stl" scale="0.001 0.001 0.001"/>
      </geometry>
    </collision>
    <inertial>
      <origin rpy="0 0 0" xyz="0.0286 0.0114 0.00028"/>
      <mass value="0.0013722"/>
      <inertia ixx="4.499197e-05" ixy="-5.286863e-05" ixz="1.07479e-06" iyy="0.00019412525" iyz="4.4041e-07" izz="0.00021338222"/>
    </inertial>
  </link>
  <joint name="end_effector_joint_R2" type="fixed">
    <origin rpy="0 0 0" xyz="0.13 0 0"/>
    <parent link="tibia_R2"/>
    <child link="end_effector_R2"/>
  </joint>
  <link name="end_effector_R2">
    <inertial>
      <origin rpy="0 0 0" xyz="0 0 0"/>
      <mass value="0"/>
      <inertia ixx="0" ixy="0" ixz="0" iyy="0" iyz="0" izz="0"/>
    </inertial>
  </link>
  <joint name="virtual_body_joint_R3" type="fixed">
    <origin rpy="0 0 0" xyz="0 0 0"/>
    <parent link="body"/>
    <child link="hip_R3"/>
  </joint>
  <link name="hip_R3">
    <inertial>
      <origin rpy="0 0 0" xyz="0 0 0"/>
      <mass value="0"/>
      <inertia ixx="0" ixy="0" ixz="0" iyy="0" iyz="0" izz="0"/>
    </inertial>
  </link>
  <!-- coxa -->
  <joint name="coxa_joint_R3" type="revolute">
    <origin rpy="0 0 -2.6179938779914944" xyz="-0.09526279441628825 -0.05499999999999999 0"/>
    <parent link="hip_R3"/>
    <child link="coxa_R3"/>
    <axis xyz="0 0 1"/>
    <limit effort="100000" lower="-3.141592653589793" upper="3.141592653589793" velocity="10"/>
  </joint>
  <link name="coxa_R3">
    <collision>
      <origin rpy="0 0 0" xyz="0 0 0.002"/>
      <geometry>
        <mesh filename="file:///home/max/ROS2utorial/URDF/ros2_urdf_ws/install/my_robot_description/share/my_robot_description/meshes/collision/COXA_COLLISIONS.stl" scale="0.001 0.001 0.001"/>
      </geometry>
    </collision>
    <visual>
      <origin rpy="0 0 0" xyz="0 0 0.002"/>
      <geometry>
        <mesh filename="file:///home/max/ROS2utorial/URDF/ros2_urdf_ws/install/my_robot_description/share/my_robot_description/meshes/visual/COXA_R.stl" scale="0.001 0.001 0.001"/>
      </geometry>
      <material name="grey_pla"/>
    </visual>
    <inertial>
      <origin rpy="0 0 0" xyz="-0.00708 -0.00983 0.02613"/>
      <mass value="0.011045"/>
      <inertia ixx="4.537796e-05" ixy="8.0667e-07" ixz="-2.6225e-07" iyy="3.512955e-05" iyz="-3.4651e-07" izz="5.818289e-05"/>
    </inertial>
  </link>
  <!-- femur -->
  <joint name="femur_joint_R3" type="revolute">
    <origin rpy="1.5707963267948966 0 0" xyz="0.04 0 0"/>
    <parent link="coxa_R3"/>
    <child link="femur_R3"/>
    <axis xyz="0 0 1"/>
    <limit effort="100000" lower="-3.141592653589793" upper="3.141592653589793" velocity="10"/>
  </joint>
  <link name="femur_R3">
    <visual>
      <origin rpy="0 0 0" xyz="0 0 0"/>
      <geometry>
        <mesh filename="file:///home/max/ROS2utorial/URDF/ros2_urdf_ws/install/my_robot_description/share/my_robot_description/meshes/visual/FEMUR_R.stl" scale="0.001 0.001 0.001"/>
      </geometry>
      <material name="white_pla"/>
    </visual>
    <collision>
      <origin rpy="0 0 0" xyz="0 0 0"/>
      <geometry>
        <mesh filename="file:///home/max/ROS2utorial/URDF/ros2_urdf_ws/install/my_robot_description/share/my_robot_description/meshes/collision/FEMUR_R_COLLISIONS.stl" scale="0.001 0.001 0.001"/>
      </geometry>
    </collision>
    <inertial>
      <origin rpy="0 0 0" xyz="0.035 0.00305 0.03111"/>
      <mass value="0.00514"/>
      <inertia ixx="3.795796e-05" ixy="0" ixz="0" iyy="7.254033e-05" iyz="2.1619e-07" izz="4.000019e-05"/>
    </inertial>
  </link>
  <!-- tibia -->
  <joint name="tibia_joint_R3" type="revolute">
    <origin rpy="0 0 0" xyz="0.07 0 0"/>
    <parent link="femur_R3"/>
    <child link="tibia_R3"/>
    <axis xyz="0 0 1"/>
    <limit effort="100000" lower="-3.141592653589793" upper="3.141592653589793" velocity="10"/>
  </joint>
  <link name="tibia_R3">
    <visual>
      <origin rpy="0 0 -0.2617993877991494" xyz="0 0 0"/>
      <geometry>
        <mesh filename="file:///home/max/ROS2utorial/URDF/ros2_urdf_ws/install/my_robot_description/share/my_robot_description/meshes/visual/TIBIA_R.stl" scale="0.001 0.001 0.001"/>
      </geometry>
      <material name="red_pla"/>
    </visual>
    <collision>
      <origin rpy="0 0 -0.2617993877991494" xyz="0 0 0"/>
      <geometry>
        <mesh filename="file:///home/max/ROS2utorial/URDF/ros2_urdf_ws/install/my_robot_description/share/my_robot_description/meshes/collision/TIBIA_COLLISIONS.stl" scale="0.001 0.001 0.001"/>
      </geometry>
    </collision>
    <inertial>
      <origin rpy="0 0 0" xyz="0.0286 0.0114 0.00028"/>
      <mass value="0.0013722"/>
      <inertia ixx="4.499197e-05" ixy="-5.286863e-05" ixz="1.07479e-06" iyy="0.00019412525" iyz="4.4041e-07" izz="0.00021338222"/>
    </inertial>
  </link>
  <joint name="end_effector_joint_R3" type="fixed">
    <origin rpy="0 0 0" xyz="0.13 0 0"/>
    <parent link="tibia_R3"/>
    <child link="end_effector_R3"/>
  </joint>
  <link name="end_effector_R3">
    <inertial>
      <origin rpy="0 0 0" xyz="0 0 0"/>
      <mass value="0"/>
      <inertia ixx="0" ixy="0" ixz="0" iyy="0" iyz="0" izz="0"/>
    </inertial>
  </link>
  <joint name="virtual_body_joint_L1" type="fixed">
    <origin rpy="0 0 0" xyz="0 0 0"/>
    <parent link="body"/>
    <child link="hip_L1"/>
  </joint>
  <link name="hip_L1">
    <inertial>
      <origin rpy="0 0 0" xyz="0 0 0"/>
      <mass value="0"/>
      <inertia ixx="0" ixy="0" ixz="0" iyy="0" iyz="0" izz="0"/>
    </inertial>
  </link>
  <!-- coxa -->
  <joint name="coxa_joint_L1" type="revolute">
    <origin rpy="0 0 0.5235987755982988" xyz="0.09526279441628825 0.05499999999999999 0"/>
    <parent link="hip_L1"/>
    <child link="coxa_L1"/>
    <axis xyz="0 0 1"/>
    <limit effort="100000" lower="-3.141592653589793" upper="3.141592653589793" velocity="10"/>
  </joint>
  <link name="coxa_L1">
    <collision>
      <origin rpy="0 0 0" xyz="0 0 0.002"/>
      <geometry>
        <mesh filename="file:///home/max/ROS2utorial/URDF/ros2_urdf_ws/install/my_robot_description/share/my_robot_description/meshes/collision/COXA_COLLISIONS.stl" scale="0.001 0.001 0.001"/>
      </geometry>
    </collision>
    <visual>
      <origin rpy="0 0 0" xyz="0 0 0.002"/>
      <geometry>
        <mesh filename="file:///home/max/ROS2utorial/URDF/ros2_urdf_ws/install/my_robot_description/share/my_robot_description/meshes/visual/COXA_L.stl" scale="0.001 0.001 0.001"/>
      </geometry>
      <material name="grey_pla"/>
    </visual>
    <inertial>
      <origin rpy="0 0 0" xyz="-0.00708 -0.00983 -0.02613"/>
      <mass value="0.011045"/>
      <inertia ixx="4.537142e-05" ixy="8.0668e-07" ixz="2.5971e-07" iyy="3.512301e-05" iyz="3.3767e-07" izz="5.818289e-05"/>
    </inertial>
  </link>
  <!-- femur -->
  <joint name="femur_joint_L1" type="revolute">
    <origin rpy="1.5707963267948966 0 0" xyz="0.04 0 0"/>
    <parent link="coxa_L1"/>
    <child link="femur_L1"/>
    <axis xyz="0 0 1"/>
    <limit effort="100000" lower="-3.141592653589793" upper="3.141592653589793" velocity="10"/>
  </joint>
  <link name="femur_L1">
    <visual>
      <origin rpy="0 0 0" xyz="0 0 0"/>
      <geometry>
        <mesh filename="file:///home/max/ROS2utorial/URDF/ros2_urdf_ws/install/my_robot_description/share/my_robot_description/meshes/visual/FEMUR_L.stl" scale="0.001 0.001 0.001"/>
      </geometry>
      <material name="white_pla"/>
    </visual>
    <collision>
      <origin rpy="0 0 0" xyz="0 0 0"/>
      <geometry>
        <mesh filename="file:///home/max/ROS2utorial/URDF/ros2_urdf_ws/install/my_robot_description/share/my_robot_description/meshes/collision/FEMUR_L_COLLISIONS.stl" scale="0.001 0.001 0.001"/>
      </geometry>
    </collision>
    <inertial>
      <origin rpy="0 0 0" xyz="0.035 0.00305 -0.03111"/>
      <mass value="0.00514"/>
      <inertia ixx="3.795796e-05" ixy="0" ixz="0" iyy="7.254033e-05" iyz="-2.1619e-07" izz="4.000019e-05"/>
    </inertial>
  </link>
  <!-- tibia -->
  <joint name="tibia_joint_L1" type="revolute">
    <origin rpy="0 0 0" xyz="0.07 0 0"/>
    <parent link="femur_L1"/>
    <child link="tibia_L1"/>
    <axis xyz="0 0 1"/>
    <limit effort="100000" lower="-3.141592653589793" upper="3.141592653589793" velocity="10"/>
  </joint>
  <link name="tibia_L1">
    <visual>
      <origin rpy="0 0 -0.2617993877991494" xyz="0 0 0"/>
      <geometry>
        <mesh filename="file:///home/max/ROS2utorial/URDF/ros2_urdf_ws/install/my_robot_description/share/my_robot_description/meshes/visual/TIBIA_L.stl" scale="0.001 0.001 0.001"/>
      </geometry>
      <material name="red_pla"/>
    </visual>
    <collision>
      <origin rpy="0 0 -0.2617993877991494" xyz="0 0 0"/>
      <geometry>
        <mesh filename="file:///home/max/ROS2utorial/URDF/ros2_urdf_ws/install/my_robot_description/share/my_robot_description/meshes/collision/TIBIA_COLLISIONS.stl" scale="0.001 0.001 0.001"/>
      </geometry>
    </collision>
    <inertial>
      <origin rpy="0 0 0" xyz="0.0286 0.0114 -0.00028"/>
      <mass value="0.0013722"/>
      <inertia ixx="4.499197e-05" ixy="-5.286863e-05" ixz="-1.07478e-06" iyy="0.00019412525" iyz="-4.4041e-07" izz="0.00021338222"/>
    </inertial>
  </link>
  <joint name="end_effector_joint_L1" type="fixed">
    <origin rpy="0 0 0" xyz="0.13 0 0"/>
    <parent link="tibia_L1"/>
    <child link="end_effector_L1"/>
  </joint>
  <link name="end_effector_L1">
    <inertial>
      <origin rpy="0 0 0" xyz="0 0 0"/>
      <mass value="0"/>
      <inertia ixx="0" ixy="0" ixz="0" iyy="0" iyz="0" izz="0"/>
    </inertial>
  </link>
  <joint name="virtual_body_joint_L2" type="fixed">
    <origin rpy="0 0 0" xyz="0 0 0"/>
    <parent link="body"/>
    <child link="hip_L2"/>
  </joint>
  <link name="hip_L2">
    <inertial>
      <origin rpy="0 0 0" xyz="0 0 0"/>
      <mass value="0"/>
      <inertia ixx="0" ixy="0" ixz="0" iyy="0" iyz="0" izz="0"/>
    </inertial>
  </link>
  <!-- coxa -->
  <joint name="coxa_joint_L2" type="revolute">
    <origin rpy="0 0 1.5707963267948966" xyz="5.5109105961630896e-18 0.09 0"/>
    <parent link="hip_L2"/>
    <child link="coxa_L2"/>
    <axis xyz="0 0 1"/>
    <limit effort="100000" lower="-3.141592653589793" upper="3.141592653589793" velocity="10"/>
  </joint>
  <link name="coxa_L2">
    <collision>
      <origin rpy="0 0 0" xyz="0 0 0.002"/>
      <geometry>
        <mesh filename="file:///home/max/ROS2utorial/URDF/ros2_urdf_ws/install/my_robot_description/share/my_robot_description/meshes/collision/COXA_COLLISIONS.stl" scale="0.001 0.001 0.001"/>
      </geometry>
    </collision>
    <visual>
      <origin rpy="0 0 0" xyz="0 0 0.002"/>
      <geometry>
        <mesh filename="file:///home/max/ROS2utorial/URDF/ros2_urdf_ws/install/my_robot_description/share/my_robot_description/meshes/visual/COXA_L.stl" scale="0.001 0.001 0.001"/>
      </geometry>
      <material name="grey_pla"/>
    </visual>
    <inertial>
      <origin rpy="0 0 0" xyz="-0.00708 -0.00983 -0.02613"/>
      <mass value="0.011045"/>
      <inertia ixx="4.537142e-05" ixy="8.0668e-07" ixz="2.5971e-07" iyy="3.512301e-05" iyz="3.3767e-07" izz="5.818289e-05"/>
    </inertial>
  </link>
  <!-- femur -->
  <joint name="femur_joint_L2" type="revolute">
    <origin rpy="1.5707963267948966 0 0" xyz="0.04 0 0"/>
    <parent link="coxa_L2"/>
    <child link="femur_L2"/>
    <axis xyz="0 0 1"/>
    <limit effort="100000" lower="-3.141592653589793" upper="3.141592653589793" velocity="10"/>
  </joint>
  <link name="femur_L2">
    <visual>
      <origin rpy="0 0 0" xyz="0 0 0"/>
      <geometry>
        <mesh filename="file:///home/max/ROS2utorial/URDF/ros2_urdf_ws/install/my_robot_description/share/my_robot_description/meshes/visual/FEMUR_L.stl" scale="0.001 0.001 0.001"/>
      </geometry>
      <material name="white_pla"/>
    </visual>
    <collision>
      <origin rpy="0 0 0" xyz="0 0 0"/>
      <geometry>
        <mesh filename="file:///home/max/ROS2utorial/URDF/ros2_urdf_ws/install/my_robot_description/share/my_robot_description/meshes/collision/FEMUR_L_COLLISIONS.stl" scale="0.001 0.001 0.001"/>
      </geometry>
    </collision>
    <inertial>
      <origin rpy="0 0 0" xyz="0.035 0.00305 -0.03111"/>
      <mass value="0.00514"/>
      <inertia ixx="3.795796e-05" ixy="0" ixz="0" iyy="7.254033e-05" iyz="-2.1619e-07" izz="4.000019e-05"/>
    </inertial>
  </link>
  <!-- tibia -->
  <joint name="tibia_joint_L2" type="revolute">
    <origin rpy="0 0 0" xyz="0.07 0 0"/>
    <parent link="femur_L2"/>
    <child link="tibia_L2"/>
    <axis xyz="0 0 1"/>
    <limit effort="100000" lower="-3.141592653589793" upper="3.141592653589793" velocity="10"/>
  </joint>
  <link name="tibia_L2">
    <visual>
      <origin rpy="0 0 -0.2617993877991494" xyz="0 0 0"/>
      <geometry>
        <mesh filename="file:///home/max/ROS2utorial/URDF/ros2_urdf_ws/install/my_robot_description/share/my_robot_description/meshes/visual/TIBIA_L.stl" scale="0.001 0.001 0.001"/>
      </geometry>
      <material name="red_pla"/>
    </visual>
    <collision>
      <origin rpy="0 0 -0.2617993877991494" xyz="0 0 0"/>
      <geometry>
        <mesh filename="file:///home/max/ROS2utorial/URDF/ros2_urdf_ws/install/my_robot_description/share/my_robot_description/meshes/collision/TIBIA_COLLISIONS.stl" scale="0.001 0.001 0.001"/>
      </geometry>
    </collision>
    <inertial>
      <origin rpy="0 0 0" xyz="0.0286 0.0114 -0.00028"/>
      <mass value="0.0013722"/>
      <inertia ixx="4.499197e-05" ixy="-5.286863e-05" ixz="-1.07478e-06" iyy="0.00019412525" iyz="-4.4041e-07" izz="0.00021338222"/>
    </inertial>
  </link>
  <joint name="end_effector_joint_L2" type="fixed">
    <origin rpy="0 0 0" xyz="0.13 0 0"/>
    <parent link="tibia_L2"/>
    <child link="end_effector_L2"/>
  </joint>
  <link name="end_effector_L2">
    <inertial>
      <origin rpy="0 0 0" xyz="0 0 0"/>
      <mass value="0"/>
      <inertia ixx="0" ixy="0" ixz="0" iyy="0" iyz="0" izz="0"/>
    </inertial>
  </link>
  <joint name="virtual_body_joint_L3" type="fixed">
    <origin rpy="0 0 0" xyz="0 0 0"/>
    <parent link="body"/>
    <child link="hip_L3"/>
  </joint>
  <link name="hip_L3">
    <inertial>
      <origin rpy="0 0 0" xyz="0 0 0"/>
      <mass value="0"/>
      <inertia ixx="0" ixy="0" ixz="0" iyy="0" iyz="0" izz="0"/>
    </inertial>
  </link>
  <!-- coxa -->
  <joint name="coxa_joint_L3" type="revolute">
    <origin rpy="0 0 2.6179938779914944" xyz="-0.09526279441628825 0.05499999999999999 0"/>
    <parent link="hip_L3"/>
    <child link="coxa_L3"/>
    <axis xyz="0 0 1"/>
    <limit effort="100000" lower="-3.141592653589793" upper="3.141592653589793" velocity="10"/>
  </joint>
  <link name="coxa_L3">
    <collision>
      <origin rpy="0 0 0" xyz="0 0 0.002"/>
      <geometry>
        <mesh filename="file:///home/max/ROS2utorial/URDF/ros2_urdf_ws/install/my_robot_description/share/my_robot_description/meshes/collision/COXA_COLLISIONS.stl" scale="0.001 0.001 0.001"/>
      </geometry>
    </collision>
    <visual>
      <origin rpy="0 0 0" xyz="0 0 0.002"/>
      <geometry>
        <mesh filename="file:///home/max/ROS2utorial/URDF/ros2_urdf_ws/install/my_robot_description/share/my_robot_description/meshes/visual/COXA_L.stl" scale="0.001 0.001 0.001"/>
      </geometry>
      <material name="grey_pla"/>
    </visual>
    <inertial>
      <origin rpy="0 0 0" xyz="-0.00708 -0.00983 -0.02613"/>
      <mass value="0.011045"/>
      <inertia ixx="4.537142e-05" ixy="8.0668e-07" ixz="2.5971e-07" iyy="3.512301e-05" iyz="3.3767e-07" izz="5.818289e-05"/>
    </inertial>
  </link>
  <!-- femur -->
  <joint name="femur_joint_L3" type="revolute">
    <origin rpy="1.5707963267948966 0 0" xyz="0.04 0 0"/>
    <parent link="coxa_L3"/>
    <child link="femur_L3"/>
    <axis xyz="0 0 1"/>
    <limit effort="100000" lower="-3.141592653589793" upper="3.141592653589793" velocity="10"/>
  </joint>
  <link name="femur_L3">
    <visual>
      <origin rpy="0 0 0" xyz="0 0 0"/>
      <geometry>
        <mesh filename="file:///home/max/ROS2utorial/URDF/ros2_urdf_ws/install/my_robot_description/share/my_robot_description/meshes/visual/FEMUR_L.stl" scale="0.001 0.001 0.001"/>
      </geometry>
      <material name="white_pla"/>
    </visual>
    <collision>
      <origin rpy="0 0 0" xyz="0 0 0"/>
      <geometry>
        <mesh filename="file:///home/max/ROS2utorial/URDF/ros2_urdf_ws/install/my_robot_description/share/my_robot_description/meshes/collision/FEMUR_L_COLLISIONS.stl" scale="0.001 0.001 0.001"/>
      </geometry>
    </collision>
    <inertial>
      <origin rpy="0 0 0" xyz="0.035 0.00305 -0.03111"/>
      <mass value="0.00514"/>
      <inertia ixx="3.795796e-05" ixy="0" ixz="0" iyy="7.254033e-05" iyz="-2.1619e-07" izz="4.000019e-05"/>
    </inertial>
  </link>
  <!-- tibia -->
  <joint name="tibia_joint_L3" type="revolute">
    <origin rpy="0 0 0" xyz="0.07 0 0"/>
    <parent link="femur_L3"/>
    <child link="tibia_L3"/>
    <axis xyz="0 0 1"/>
    <limit effort="100000" lower="-3.141592653589793" upper="3.141592653589793" velocity="10"/>
  </joint>
  <link name="tibia_L3">
    <visual>
      <origin rpy="0 0 -0.2617993877991494" xyz="0 0 0"/>
      <geometry>
        <mesh filename="file:///home/max/ROS2utorial/URDF/ros2_urdf_ws/install/my_robot_description/share/my_robot_description/meshes/visual/TIBIA_L.stl" scale="0.001 0.001 0.001"/>
      </geometry>
      <material name="red_pla"/>
    </visual>
    <collision>
      <origin rpy="0 0 -0.2617993877991494" xyz="0 0 0"/>
      <geometry>
        <mesh filename="file:///home/max/ROS2utorial/URDF/ros2_urdf_ws/install/my_robot_description/share/my_robot_description/meshes/collision/TIBIA_COLLISIONS.stl" scale="0.001 0.001 0.001"/>
      </geometry>
    </collision>
    <inertial>
      <origin rpy="0 0 0" xyz="0.0286 0.0114 -0.00028"/>
      <mass value="0.0013722"/>
      <inertia ixx="4.499197e-05" ixy="-5.286863e-05" ixz="-1.07478e-06" iyy="0.00019412525" iyz="-4.4041e-07" izz="0.00021338222"/>
    </inertial>
  </link>
  <joint name="end_effector_joint_L3" type="fixed">
    <origin rpy="0 0 0" xyz="0.13 0 0"/>
    <parent link="tibia_L3"/>
    <child link="end_effector_L3"/>
  </joint>
  <link name="end_effector_L3">
    <inertial>
      <origin rpy="0 0 0" xyz="0 0 0"/>
      <mass value="0"/>
      <inertia ixx="0" ixy="0" ixz="0" iyy="0" iyz="0" izz="0"/>
    </inertial>
  </link>
</robot>
